Workbook

Sheet 00_README
A1: 福岡県 事業者集計（基本一覧×施設基準 結合・改訂版）
A3: 【元データ】①保険薬局一覧(令和8年6月1日現在) ②施設基準届出状況(令和8年5月1日現在)／九州厚生局
A4: 出典URL: https://kouseikyoku.mhlw.go.jp/kyushu/gyomu/gyomu/hoken_kikan/index_00004.html
A5: ①r8_06_fukuoka_yakkyoku_02.xlsx（開設者法人）× ②r8_05_shisetsu_fukuoka_yakkyoku_02.xlsx（在宅フラグ）を保険薬局コードで結合。
A6: 結合率: 施設側2,943件のうち基本一覧と突合可能（在宅フラグ＋法人名を両取り）。
A8: 【在宅の定義】◎在宅薬学総合体制加算1or2 ／ ○在宅患者訪問薬剤管理指導料（広義）
A10: 【名寄せ】開設者法人をキーに辞書(01)で正規化。法人があるため屋号より高精度（例: 屋号さくら薬局→法人なの花九州を正しく識別）。
A11: 要確認名は 03_要確認修正 で全域解消済（さくら薬局/さくら調剤/すこやか薬局）。
A13: 【シート】01_名寄せ辞書 / 02_名寄せ履歴 / 03_要確認修正 / 10_ローデータ / 20_集計_全薬局事業者別 / 21_集計_在宅事業者別
A14: 20=在宅フィルタ無しの全薬局シェア、21=在総ベースの在宅事業者ランキング。いずれもCOUNTIFS数式。

Sheet 01_名寄せ辞書
A1: 名寄せ辞書（大手・主要チェーン／改訂版）
A2: 上から順に評価し最初に一致したルールを採用（first match wins）。福岡は開設者法人、非福岡は屋号に対して照合。未一致は『中小・独立』。
A4: ルールID | B4: 正規化事業者名 | C4: タイプ | D4: 親会社・メモ | E4: 信頼度 | F4: マッチ語（部分一致）
A5: R01 | B5: アインホールディングス（アイン薬局） | C5: 大手全国 | D5: 東証PRM・国内最大手 | E5: 高 | F5: アインファーマシーズ；アイン薬局；アインメディオ
A6: R02 | B6: 総合メディカル（そうごう薬局） | C6: 大手全国 | D6: SOGO MEDICAL・福岡発祥の全国大手 | E6: 高 | F6: 総合メディカル；そうごう薬局；ソウゴウ薬局
A7: R03 | B7: 日本調剤 | C7: 大手全国 | D7: 東証PRM | E7: 高 | F7: 日本調剤
A8: R04 | B8: クオール（クオール薬局） | C8: 大手全国 | D8: 東証PRM | E8: 高 | F8: クオール
A9: R05 | B9: メディカルシステムネットワーク（なの花薬局） | C9: 大手全国 | D9: 札幌発祥・なの花・九州はなの花九州／さくら薬局屋号も同社系が多い | E9: 高 | F9: なの花；メディカルシステムネットワーク
A10: R06 | B10: クラフト（さくら薬局グループ） | C10: 大手全国 | D10: ※「さくら薬局」屋号は九州ではなの花九州系が大半→屋号では集約せず法人名でのみ判定 | E10: 中 | F10: クラフト株式会社；クラフト
A11: R07 | B11: HYUGA PRIMARY CARE（きらり薬局） | C11: 在宅特化・上場 | D11: 東証GRT・分析対象本命 | E11: 高 | F11: ＨＹＵＧＡ；HYUGA；きらり薬局
A12: R08 | B12: ウエルシアHD（イオン系） | C12: ドラッグ大手 | D12: 調剤併設 | E12: 高 | F12: ウエルシア；イオンウエルシア
A13: R09 | B13: ツルハHD | C13: ドラッグ大手 | D13: 調剤併設 | E13: 高 | F13: ツルハ；くすりの福太郎
A14: R10 | B14: マツキヨココカラ&Co | C14: ドラッグ大手 | D14: 調剤併設 | E14: 高 | F14: ココカラファイン；マツモトキヨシ
A15: R11 | B15: スギHD（スギ薬局） | C15: ドラッグ大手 | D15: 調剤併設 | E15: 高 | F15: スギ薬局；スギホールディングス
... A20: R24 | B20: 溝上薬局 | C20: 地場大手(福岡) | D20: 福岡・九州で展開 | E20: 高 | F20: 溝上薬局
A21: R25 | B21: タケシタ調剤薬局 | C21: 地場(福岡・熊本) | E21: 高 | F21: タケシタ
A22: R26 | B22: コスモス薬品 | C22: ドラッグ(九州発) | D22: ディスカウントドラッグコスモス | E22: 高 | F22: コスモス薬品；ディスカウントドラッグコスモス
A23: R27 | B23: ドラッグストアモリ | C23: ドラッグ(九州) | E23: 高 | F23: ドラッグストアモリ
A24: R28 | B24: ドラッグイレブン | C24: ドラッグ(九州) | D24: JR九州系 | E24: 中 | F24: ドラッグイレブン
A25: R29 | B25: 大信薬局 | C25: 地場(福岡) | D25: 在宅・施設に注力 | E25: 中 | F25: 大信薬局
A26: R30 | B26: ニック（ニック調剤薬局） | C26: 地場(九州) | E26: 中 | F26: ニック
A27: R31 | B27: アガペ | C27: 地場(福岡) | E27: 中 | F27: アガペ
A28: R32 | B28: ミズ | C28: 地場(福岡) | E28: 中 | F28: 株式会社ミズ；ミズ薬局
A29: R33 | B29: タカサキ（高崎）薬局 | C29: 地場 | E29: 中 | F29: タカサキ；高崎薬局
A30: R40 | B30: すこやか薬局（沖縄地盤） | C30: 地場(沖縄) | D30: 沖縄45店の単一チェーン。熊本/長崎の同名は別法人の可能性（屋号一致のため混入注意） | E30: 中 | F30: すこやか薬局

Sheet 02_名寄せ履歴
A1: 名寄せ履歴（監査用：原名称→適用ルール→正規化事業者）
A2: 原データの『開設者法人/屋号』を一意化し、どのルールで・どの事業者へ寄せたかを全件表示。件数合計はローデータ行数と一致。
A4: 原・開設者法人/屋号 | B4: 名寄せ方式 | C4: 適用ルールID | D4: 正規化事業者名 | E4: タイプ | F4: 信頼度 | G4: 該当店舗数
A5: 株式会社大賀薬局 | B5: 法人 | C5: R20 | D5: 大賀薬局 | E5: 地場大手(福岡) | F5: 高 | G5: 93
A6: 総合メディカル株式会社 | B6: 法人 | C6: R02 | D6: 総合メディカル（そうごう薬局） | E6: 大手全国 | F6: 高 | G6: 72
A7: 株式会社新生堂薬局 | B7: 法人 | C7: R21 | D7: 新生堂薬局 | E7: 地場大手(福岡) | F7: 高 | G7: 57
A8: 株式会社タカラ薬局 | B8: 法人 | C8: R23 | D8: タカラ薬局（大蔵商事/タカラ） | E8: 地場(福岡) | F8: 中 | G8: 44
A9: 株式会社サンキュードラッグ | B9: 法人 | C9: R22 | D9: サンキュードラッグ | E9: 地場(北九州) | F9: 高 | G9: 44
A10: 株式会社なの花九州 | B10: 法人 | C10: R05 | D10: メディカルシステムネットワーク（なの花薬局） | E10: 大手全国 | F10: 高 | G10: 42
A11: 株式会社アガペ | B11: 法人 | C11: R31 | D11: アガペ | E11: 地場(福岡) | F11: 中 | G11: 38
A12: ＨＹＵＧＡ ＰＲＩＭＡＲＹ ＣＡＲＥ株式会社 | B12: 法人 | C12: R07 | D12: HYUGA PRIMARY CARE（きらり薬局） | E12: 在宅特化・上場 | F12: 高 | G12: 36
A13: 株式会社ニック | B13: 法人 | C13: R30 | D13: ニック（ニック調剤薬局） | E13: 地場(九州) | F13: 中 | G13: 26
A14: 株式会社アインファーマシーズ | B14: 法人 | C14: R01 | D14: アインホールディングス（アイン薬局） | E14: 大手全国 | F14: 高 | G14: 19
A15: 株式会社ドラッグストアモリ | B15: 法人 | C15: R27 | D15: ドラッグストアモリ | E15: ドラッグ(九州) | F15: 高 | G15: 17
A16: 株式会社ツルハグループドラッグ＆ファーマシー西日本 | B16: 法人 | C16: R09 | D16: ツルハHD | E16: ドラッグ大手 | F16: 高 | G16: 17
... A1347: ケンコーミライ株式会社 | B1347: 法人 | C1347: - | D1347: ケンコーミライ株式会社 | E1347: 中小・独立 | F1347: 自動 | G1347: 1
F1348: 合計 | G1348: =SUM(G5:G1347)

Sheet 03_要確認修正
A1: 要確認名寄せの解消記録（全域で適用）
A2: 汎用屋号・誤集約を実データ（特に福岡の法人内訳）で検証し、辞書を修正した履歴。
A4: 対象 | B4: 調査結果（根拠） | C4: 旧マッピング | D4: 新マッピング（適用済） | E4: 影響 | F4: 信頼度
A5: さくら薬局 | B5: 福岡58件の法人内訳＝なの花九州41／クラフト1／有限会社さくら薬局3／他独立。屋号『さくら薬局』はなの花九州系（R05）が大半でクラフトは僅少。 | C5: R06『クラフト（さくら薬局）』へ屋号一致で全件誤集約 | D5: R06のエイリアスから『さくら薬局』を削除。福岡は法人で正しく分解（なの花九州→R05等）、非福岡は屋号baseで独立計上（同名異法人は分離不可と明記） | E5: 福岡の さくら薬局≈41店が クラフト→メディカルSN(なの花) へ是正 | F5: 高
A6: さくら調剤薬局 | B6: 福岡5件で法人4社混在（さくら調剤/おおじま調剤/中商/朝倉ファーマシー）。旧ルールは『あさくら調剤薬局』も誤マッチ。 | C6: R41『さくら調剤薬局』を単一事業者として集約 | D6: R41を廃止。福岡は法人で分解。非福岡は屋号base『さくら調剤』で計上（同名複数法人の可能性を注記）。『あさくら』は別baseで自動分離 | E6: 単一チェーンの誤認を解消（実態は複数法人） | F6: 高
A7: すこやか薬局 | B7: 全47件中 沖縄45・熊本1・長崎1。沖縄45は屋号＋店名で単一チェーンと判断。 | C7: R40 要確認（同名複数の可能性） | D7: R40『すこやか薬局（沖縄地盤）』として確定（信頼度中）。熊本/長崎の同名2件は別法人の可能性ありと注記し屋号一致で混入する点を明示 | E7: 沖縄チェーンとして確定、2件の他県同名は誤差 | F7: 中
A8: （全般）屋号ベースの限界 | B8: 非福岡7県は施設基準ファイルに開設者法人列が無く屋号でしか名寄せできない。 | C8: － | D8: 同名異法人（ひまわり/あおぞら/さくら調剤等）は分離不可。大手は法人裏付けのある福岡＋全国チェーン辞書で担保。生データに屋号コアを残し追跡可能に | E8: 中小・独立カテゴリは過小/過大の双方向誤差を含みうる | F8: 中

Sheet 10_ローデータ
A1: No | B1: 保険薬局コード | C1: 薬局名称(屋号) | D1: 所在地 | E1: 開設者法人 | F1: 適用ルールID | G1: 正規化事業者名 | H1: 事業者タイプ | I1: 信頼度 | J1: 在総1 | K1: 在総2 | L1: 在総(1or2) | M1: 在薬(訪問届出)
A2: 1 | B2: 0240006 | C2: 福薬局箱崎駅前店 | D2: 福岡市東区箱崎三丁目５番４２号１Ｆ | E2: 有限会社福神 | F2: - | G2: 有限会社福神 | H2: 中小・独立 | I2: 自動 | J2: 1 | K2: 0 | L2: 1 | M2: 1
A3: 2 | B3: 0341689 | C3: 株式会社 朝日調剤薬局 | D3: 福岡県福岡市博多区博多駅前２丁目１番１号 | E3: 株式会社 朝日調剤薬局 | F3: - | G3: 株式会社 朝日調剤薬局 | H3: 中小・独立 | I3: 自動 | J3: 1 | K3: 0 | L3: 1 | M3: 1
A4: 3 | B4: 0341903 | C4: 株式会社 ふじの薬局 | D4: 福岡県福岡市東区箱崎２丁目９番２８号 | E4: 株式会社 ふじの薬局 | F4: - | G4: 株式会社 ふじの薬局 | H4: 中小・独立 | I4: 自動 | J4: 0 | K4: 0 | L4: 0 | M4: 1
A5: 4 | B5: 0342083 | C5: 保生堂調剤薬局 | D5: 福岡県福岡市博多区上呉服町１０番２３号 | E5: 株式会社保生堂 | F5: - | G5: 株式会社保生堂 | H5: 中小・独立 | I5: 自動 | J5: 1 | K5: 0 | L5: 1 | M5: 1
A6: 5 | B6: 0342216 | C6: 有限会社 ミトク薬局 | D6: 福岡県福岡市博多区祇園町４番７９号 | E6: 有限会社 ミトク薬局 | F6: - | G6: 有限会社 ミトク薬局 | H6: 中小・独立 | I6: 自動 | J6: 0 | K6: 0 | L6: 0 | M6: 1
A7: 6 | B7: 0342281 | C7: 有限会社 ミトク薬局 南福岡店 | D7: 福岡県福岡市博多区南本町２丁目４番１６号 | E7: 有限会社 ミトク薬局 | F7: - | G7: 有限会社 ミトク薬局 | H7: 中小・独立 | I7: 自動 | J7: 0 | K7: 0 | L7: 0 | M7: 1
A8: 7 | B8: 0342414 | C8: 香椎薬親会薬局 | D8: 福岡県福岡市東区香椎駅前二丁目１０番３号 | E8: 有限会社薬親会薬局 | F8: - | G8: 有限会社薬親会薬局 | H8: 中小・独立 | I8: 自動 | J8: 0 | K8: 0 | L8: 0 | M8: 1
A9: 8 | B9: 0342455 | C9: 裕生堂薬局 中洲店 | D9: 福岡県福岡市博多区中洲５丁目５番２１号 | E9: 株式会社裕生堂 | F9: - | G9: 株式会社裕生堂 | H9: 中小・独立 | I9: 自動 | J9: 1 | K9: 0 | L9: 1 | M9: 1
A10: 9 | B10: 0342547 | C10: 有限会社 馬出薬局 | D10: 福岡県福岡市東区馬出２丁目１８番１６号 | E10: 有限会社 馬出薬局 | F10: - | G10: 有限会社 馬出薬局 | H10: 中小・独立 | I10: 自動 | J10: 1 | K10: 0 | L10: 1 | M10: 1
A11: 10 | B11: 0342661 | C11: 株式会社新生堂薬局雑餉隈店 | D11: 福岡県福岡市博多区銀天町３丁目１－１０ | E11: 株式会社 新生堂薬局 | F11: R21 | G11: 新生堂薬局 | H11: 地場大手(福岡) | I11: 高 | J11: 1 | K11: 0 | L11: 1 | M11: 1
A12: 11 | B12: 0342687 | C12: 和光調剤薬局 | D12: 福岡県福岡市博多区博多駅前３丁目２３－１５ アースコート博多駅前ＢＬＤＧ． | E12: 株式会社和光薬品 | F12: - | G12: 株式会社和光薬品 | H12: 中小・独立 | I12: 自動 | J12: 0 | K12: 0 | L12: 0 | M12: 1
A13: 12 | B13: 0342695 | C13: 新生堂薬局香椎店 | D13: 福岡市東区香椎駅前二丁目１４番１１号アートラフィーネ香椎 | E13: 株式会社新生堂薬局 | F13: R21 | G13: 新生堂薬局 | H13: 地場大手(福岡) | I13: 高 | J13: 1 | K13: 0 | L13: 1 | M13: 1
... A453: 452 | B453: 0640866 | C453: さくら薬局赤間店 | D453: 宗像市須恵１丁目１６－２４ | E453: 株式会社なの花九州 | F453: R05 | G453: メディカルシステムネットワーク（なの花薬局） | H453: 大手全国 | I453: 高 | J453: 0 | K453: 0 | L453: 0 | M453: 1
A454: 453 | B454: 0640874 | C454: いなもと調剤薬局 | D454: 宗像市稲元３丁目１－６ | F454: - | G454: いなもと調剤 | H454: 中小・独立 | I454: 自動 | J454: 0 | K454: 1 | L454: 1 | M454: 1
A455: 454 | B455: 0640882 | C455: リーフ薬局 | D455: 宗像市くりえいと３－４－１５ | E455: 株式会社シーアンドアール | F455: - | G455: 株式会社シーアンドアール | H455: 中小・独立 | I455: 自動 | J455: 0 | K455: 0 | L455: 0 | M455: 1
A456: 455 | B456: 0640890 | C456: のため薬局宗像真田丸店 | D456: 宗像市田久２丁目３－１７ | E456: 株式会社オーセンティック | F456: - | G456: 株式会社オーセンティック | H456: 中小・独立 | I456: 自動 | J456: 0 | K456: 0 | L456: 0 | M456: 0
A457: 456 | B457: 0640916 | C457: マイルド薬局宗像店 | D457: 宗像市日の里８丁目３番２５号 | E457: 有限会社マイルド薬局 | F457: - | G457: 有限会社マイルド薬局 | H457: 中小・独立 | I457: 自動 | J457: 0 | K457: 0 | L457: 0 | M457: 1
A458: 457 | B458: 0740021 | C458: 株式会社 古賀薬局 東病院前店 | D458: 福岡県古賀市千鳥２丁目１－１５ | E458: 株式会社 古賀薬局 | F458: - | G458: 株式会社 古賀薬局 | H458: 中小・独立 | I458: 自動 | J458: 0 | K458: 0 | L458: 0 | M458: 1
A459: 458 | B459: 0740039 | C459: 株式会社 古賀薬局 駅前店 | D459: 福岡県古賀市天神５－５－６ | E459: 株式会社 古賀薬局 | F459: - | G459: 株式会社 古賀薬局 | H459: 中小・独立 | I459: 自動 | J459: 0 | K459: 0 | L459: 0 | M459: 1
A460: 459 | B460: 0740062 | C460: 株式会社 古賀薬局 中央店 | D460: 福岡県古賀市天神１丁目１３－３６ | E460: 株式会社 古賀薬局 | F460: - | G460: 株式会社 古賀薬局 | H460: 中小・独立 | I460: 自動 | J460: 0 | K460: 0 | L460: 0 | M460: 1
A461: 460 | B461: 0740088 | C461: サカタ薬局花見店 | D461: 福岡県古賀市花見東１丁目３－３ | E461: 坂田 博子 | F461: - | G461: 坂田 博子 | H461: 中小・独立 | I461: 自動 | J461: 0 | K461: 0 | L461: 0 | M461: 0
A462: 461 | B462: 0740120 | C462: そうごう薬局花見店 | D462: 福岡県古賀市花見南１ー３ー２５ | E462: 総合メディカル株式会社 | F462: R02 | G462: 総合メディカル（そうごう薬局） | H462: 大手全国 | I462: 高 | J462: 0 | K462: 1 | L462: 1 | M462: 1
A463: 462 | B463: 0740138 | C463: さくら薬局 舞の里店 | D463: 福岡県古賀市舞の里３丁目１７番１１号 | E463: 株式会社なの花九州 | F463: R05 | G463: メディカルシステムネットワーク（なの花薬局） | H463: 大手全国 | I463: 高 | J463: 1 | K463: 0 | L463: 1 | M463: 1
A464: 463 | B464: 0740153 | C464: 株式会社タカラ薬局 舞の里 | D464: 福岡県古賀市舞の里３丁目１５－６ | E464: 株式会社 タカラ薬局 | F464: R23 | G464: タカラ薬局（大蔵商事/タカラ） | H464: 地場(福岡) | I464: 中 | J464: 1 | K464: 0 | L464: 1 | M464: 1
A465: 464 | B465: 0740195 | C465: 有限会社オレンジ薬局 東病院前店 | D465: 福岡県古賀市千鳥２丁目３番１号 | E465: 有限会社オレンジ薬局 | F465: - | G465: 有限会社オレンジ薬局 | H465: 中小・独立 | I465: 自動 | J465: 0 | K465: 0 | L465: 0 | M465: 0
A466: 465 | B466: 0740203 | C466: そうごう薬局 久保店 | D466: 福岡県古賀市大字久保１０９７－６ | E466: 総合メディカル株式会社 | F466: R02 | G466: 総合メディカル（そうごう薬局） | H466: 大手全国 | I466: 高 | J466: 1 | K466: 0 | L466: 1 | M466: 1
... A624: 623 | B624: 1042237 | C624: 株式会社太陽薬局あけぼの店 | D624: 福岡市早良区曙一丁目５番２５号 | E624: 株式会社太陽薬局 | F624: - | G624: 株式会社太陽薬局 | H624: 中小・独立 | I624: 自動 | J624: 1 | K624: 0 | L624: 1 | M624: 1
A625: 624 | B625: 1042245 | C625: こもれび薬局 | D625: 福岡市中央区渡辺通一丁目１０番１－１０１号 | F625: - | G625: こもれび薬局 | H625: 中小・独立 | I625: 自動 | J625: 0 | K625: 0 | L625: 0 | M625: 1
A626: 625 | B626: 1042260 | C626: 野間薬局長尾店 | D626: 福岡市城南区長尾一丁目１９番７－１０２号 | E626: ＪーＦｒｏｎｔ株式会社 | F626: - | G626: ＪーＦｒｏｎｔ株式会社 | H626: 中小・独立 | I626: 自動 | J626: 0 | K626: 0 | L626: 0 | M626: 1
A627: 626 | B627: 1042278 | C627: クオール薬局福岡店 | D627: 福岡市早良区田村二丁目１５番３５号 | E627: クオール株式会社 | F627: R04 | G627: クオール（クオール薬局） | H627: 大手全国 | I627: 高 | J627: 0 | K627: 1 | L627: 1 | M627: 1
A628: 627 | B628: 1042286 | C628: マイルド調剤薬局 | D628: 福岡市中央区天神二丁目１３番１７号恒松ビル５Ｆ | E628: 株式会社アルナ薬局 | F628: - | G628: 株式会社アルナ薬局 | H628: 中小・独立 | I628: 自動 | J628: 0 | K628: 1 | L628: 1 | M628: 1
A629: 628 | B629: 1042294 | C629: 野間薬局六本松店 | D629: 福岡市中央区六本松二丁目３番２１号ルポ六本松１Ｆ | E629: Ｊ－Ｆｒｏｎｔ株式会社 | F629: - | G629: Ｊ－Ｆｒｏｎｔ株式会社 | H629: 中小・独立 | I629: 自動 | J629: 1 | K629: 0 | L629: 1 | M629: 1
A630: 629 | B630: 1042310 | C630: 日本調剤城南薬局 | D630: 福岡市城南区神松寺一丁目５番２２号 | E630: 日本調剤株式会社 | F630: R03 | G630: 日本調剤 | H630: 大手全国 | I630: 高 | J630: 0 | K630: 1 | L630: 1 | M630: 1
A631: 630 | B631: 1042328 | C631: 株式会社大賀薬局 西鉄福岡駅店 | D631: 福岡市中央区天神二丁目１１番２号Ｍ２Ｆ | E631: 株式会社大賀薬局 | F631: R20 | G631: 大賀薬局 | H631: 地場大手(福岡) | I631: 高 | J631: 0 | K631: 1 | L631: 1 | M631: 1
A632: 631 | B632: 1042336 | C632: 和光草香江薬局 | D632: 福岡市中央区草香江一丁目１番１２号 | E632: 株式会社和光薬品 | F632: - | G632: 株式会社和光薬品 | H632: 中小・独立 | I632: 自動 | J632: 1 | K632: 0 | L632: 1 | M632: 1
A633: 632 | B633: 1042344 | C633: ゆず薬局 | D633: 福岡市早良区小田部五丁目７番７号 | E633: 株式会社ファーストドリーム | F633: - | G633: 株式会社ファーストドリーム | H633: 中小・独立 | I633: 自動 | J633: 0 | K633: 0 | L633: 0 | M633: 0
A634: 633 | B634: 1042377 | C634: 野間薬局東入部店 | D634: 福岡市早良区東入部六丁目２６番７号 | E634: Ｊ－Ｆｒｏｎｔ株式会社 | F634: - | G634: Ｊ－Ｆｒｏｎｔ株式会社 | H634: 中小・独立 | I634: 自動 | J634: 0 | K634: 0 | L634: 0 | M634: 1
A635: 634 | B635: 1042393 | C635: アガペ姪浜薬局 | D635: 福岡市西区姪の浜五丁目９番１号 | E635: 株式会社アガペ | F635: R31 | G635: アガペ | H635: 地場(福岡) | I635: 中 | J635: 1 | K635: 0 | L635: 1 | M635: 1
A636: 635 | B636: 1042401 | C636: 株式会社大賀薬局早良１丁目店 | D636: 福岡市早良区早良一丁目５番４８号 | E636: 株式会社大賀薬局 | F636: R20 | G636: 大賀薬局 | H636: 地場大手(福岡) | I636: 高 | J636: 1 | K636: 0 | L636: 1 | M636: 1
...

Sheet 20_集計_全薬局事業者別
A1: 福岡県 事業者別 店舗数（全薬局・在宅フィルタ無）
A2: 店舗数=COUNTIF(正規化事業者)。並びは大手優先＋店舗数降順。
A4: 順位 | B4: 正規化事業者名 | C4: 事業者タイプ | D4: 信頼度 | E4: 店舗数 | F4: シェア
A5: 1 | B5: 大賀薬局 | C5: 地場大手(福岡) | D5: 高 | E5: =COUNTIF('10_ローデータ'!G:G,B5) | F5: =E5/$E$1328
A6: 2 | B6: 総合メディカル（そうごう薬局） | C6: 大手全国 | D6: 高 | E6: =COUNTIF('10_ローデータ'!G:G,B6) | F6: =E6/$E$1328
A7: 3 | B7: 新生堂薬局 | C7: 地場大手(福岡) | D7: 高 | E7: =COUNTIF('10_ローデータ'!G:G,B7) | F7: =E7/$E$1328
A8: 4 | B8: タカラ薬局（大蔵商事/タカラ） | C8: 地場(福岡) | D8: 中 | E8: =COUNTIF('10_ローデータ'!G:G,B8) | F8: =E8/$E$1328
A9: 5 | B9: サンキュードラッグ | C9: 地場(北九州) | D9: 高 | E9: =COUNTIF('10_ローデータ'!G:G,B9) | F9: =E9/$E$1328
A10: 6 | B10: アガペ | C10: 地場(福岡) | D10: 中 | E10: =COUNTIF('10_ローデータ'!G:G,B10) | F10: =E10/$E$1328
A11: 7 | B11: メディカルシステムネットワーク（なの花薬局） | C11: 大手全国 | D11: 高 | E11: =COUNTIF('10_ローデータ'!G:G,B11) | F11: =E11/$E$1328
A12: 8 | B12: HYUGA PRIMARY CARE（きらり薬局） | C12: 在宅特化・上場 | D12: 高 | E12: =COUNTIF('10_ローデータ'!G:G,B12) | F12: =E12/$E$1328
A13: 9 | B13: ニック（ニック調剤薬局） | C13: 地場(九州) | D13: 中 | E13: =COUNTIF('10_ローデータ'!G:G,B13) | F13: =E13/$E$1328
A14: 10 | B14: タケシタ調剤薬局 | C14: 地場(福岡・熊本) | D14: 高 | E14: =COUNTIF('10_ローデータ'!G:G,B14) | F14: =E14/$E$1328
A15: 11 | B15: 大信薬局 | C15: 地場(福岡) | D15: 中 | E15: =COUNTIF('10_ローデータ'!G:G,B15) | F15: =E15/$E$1328
A16: 12 | B16: ミズ | C16: 地場(福岡) | D16: 中 | E16: =COUNTIF('10_ローデータ'!G:G,B16) | F16: =E16/$E$1328
... A1326: 1322 | B1326: ケンコーミライ株式会社 | C1326: 中小・独立 | D1326: 自動 | E1326: =COUNTIF('10_ローデータ'!G:G,B1326) | F1326: =E1326/$E$1328
B1327: 合計（検算） | E1327: =SUM(E5:E1326)
B1328: ローデータ行数 | E1328: =COUNTA('10_ローデータ'!B2:B2944)

Sheet 21_集計_在宅事業者別
A1: 福岡県 在宅薬局 事業者別 店舗数（在宅薬学総合体制加算ベース）
A2: 在総店舗数=COUNTIFS(事業者一致 & 在総=1)。法人名寄せにより高精度。
A4: 順位 | B4: 正規化事業者名 | C4: 事業者タイプ | D4: 信頼度 | E4: 在総薬局数 | F4: 広義(在薬)薬局数 | G4: 在総シェア
A5: 1 | B5: 大賀薬局 | C5: 地場大手(福岡) | D5: 高 | E5: =COUNTIFS('10_ローデータ'!G:G,B5,'10_ローデータ'!L:L,1) | F5: =COUNTIFS('10_ローデータ'!G:G,B5,'10_ローデータ'!M:M,1) | G5: =E5/$E$594
A6: 2 | B6: 総合メディカル（そうごう薬局） | C6: 大手全国 | D6: 高 | E6: =COUNTIFS('10_ローデータ'!G:G,B6,'10_ローデータ'!L:L,1) | F6: =COUNTIFS('10_ローデータ'!G:G,B6,'10_ローデータ'!M:M,1) | G6: =E6/$E$594
A7: 3 | B7: 新生堂薬局 | C7: 地場大手(福岡) | D7: 高 | E7: =COUNTIFS('10_ローデータ'!G:G,B7,'10_ローデータ'!L:L,1) | F7: =COUNTIFS('10_ローデータ'!G:G,B7,'10_ローデータ'!M:M,1) | G7: =E7/$E$594
A8: 4 | B8: タカラ薬局（大蔵商事/タカラ） | C8: 地場(福岡) | D8: 中 | E8: =COUNTIFS('10_ローデータ'!G:G,B8,'10_ローデータ'!L:L,1) | F8: =COUNTIFS('10_ローデータ'!G:G,B8,'10_ローデータ'!M:M,1) | G8: =E8/$E$594
A9: 5 | B9: HYUGA PRIMARY CARE（きらり薬局） | C9: 在宅特化・上場 | D9: 高 | E9: =COUNTIFS('10_ローデータ'!G:G,B9,'10_ローデータ'!L:L,1) | F9: =COUNTIFS('10_ローデータ'!G:G,B9,'10_ローデータ'!M:M,1) | G9: =E9/$E$594
A10: 6 | B10: サンキュードラッグ | C10: 地場(北九州) | D10: 高 | E10: =COUNTIFS('10_ローデータ'!G:G,B10,'10_ローデータ'!L:L,1) | F10: =COUNTIFS('10_ローデータ'!G:G,B10,'10_ローデータ'!M:M,1) | G10: =E10/$E$594
A11: 7 | B11: メディカルシステムネットワーク（なの花薬局） | C11: 大手全国 | D11: 高 | E11: =COUNTIFS('10_ローデータ'!G:G,B11,'10_ローデータ'!L:L,1) | F11: =COUNTIFS('10_ローデータ'!G:G,B11,'10_ローデータ'!M:M,1) | G11: =E11/$E$594
A12: 8 | B12: アガペ | C12: 地場(福岡) | D12: 中 | E12: =COUNTIFS('10_ローデータ'!G:G,B12,'10_ローデータ'!L:L,1) | F12: =COUNTIFS('10_ローデータ'!G:G,B12,'10_ローデータ'!M:M,1) | G12: =E12/$E$594
A13: 9 | B13: 大信薬局 | C13: 地場(福岡) | D13: 中 | E13: =COUNTIFS('10_ローデータ'!G:G,B13,'10_ローデータ'!L:L,1) | F13: =COUNTIFS('10_ローデータ'!G:G,B13,'10_ローデータ'!M:M,1) | G13: =E13/$E$594
A14: 10 | B14: アインホールディングス（アイン薬局） | C14: 大手全国 | D14: 高 | E14: =COUNTIFS('10_ローデータ'!G:G,B14,'10_ローデータ'!L:L,1) | F14: =COUNTIFS('10_ローデータ'!G:G,B14,'10_ローデータ'!M:M,1) | G14: =E14/$E$594
A15: 11 | B15: ニック（ニック調剤薬局） | C15: 地場(九州) | D15: 中 | E15: =COUNTIFS('10_ローデータ'!G:G,B15,'10_ローデータ'!L:L,1) | F15: =COUNTIFS('10_ローデータ'!G:G,B15,'10_ローデータ'!M:M,1) | G15: =E15/$E$594
A16: 12 | B16: ミズ | C16: 地場(福岡) | D16: 中 | E16: =COUNTIFS('10_ローデータ'!G:G,B16,'10_ローデータ'!L:L,1) | F16: =COUNTIFS('10_ローデータ'!G:G,B16,'10_ローデータ'!M:M,1) | G16: =E16/$E$594
... A592: 588 | B592: 有限会社角田調剤薬局 | C592: 中小・独立 | D592: 自動 | E592: =COUNTIFS('10_ローデータ'!G:G,B592,'10_ローデータ'!L:L,1) | F592: =COUNTIFS('10_ローデータ'!G:G,B592,'10_ローデータ'!M:M,1) | G592: =E592/$E$594
B593: 合計（検算） | E593: =SUM(E5:E592)
B594: 在総薬局 総数 | E594: =COUNTIF('10_ローデータ'!L2:L2944,1)
